Traceback (most recent call last):
  File "/Users/feilong/miniconda3/envs/py/lib/python3.9/site-packages/jupyter_cache/executors/utils.py", line 58, in single_nb_execution
    executenb(
  File "/Users/feilong/miniconda3/envs/py/lib/python3.9/site-packages/nbclient/client.py", line 1112, in execute
    return NotebookClient(nb=nb, resources=resources, km=km, **kwargs).execute()
  File "/Users/feilong/miniconda3/envs/py/lib/python3.9/site-packages/nbclient/util.py", line 74, in wrapped
    return just_run(coro(*args, **kwargs))
  File "/Users/feilong/miniconda3/envs/py/lib/python3.9/site-packages/nbclient/util.py", line 53, in just_run
    return loop.run_until_complete(coro)
  File "/Users/feilong/miniconda3/envs/py/lib/python3.9/asyncio/base_events.py", line 642, in run_until_complete
    return future.result()
  File "/Users/feilong/miniconda3/envs/py/lib/python3.9/site-packages/nbclient/client.py", line 553, in async_execute
    await self.async_execute_cell(
  File "/Users/feilong/miniconda3/envs/py/lib/python3.9/site-packages/nbclient/client.py", line 857, in async_execute_cell
    self._check_raise_for_error(cell, exec_reply)
  File "/Users/feilong/miniconda3/envs/py/lib/python3.9/site-packages/nbclient/client.py", line 760, in _check_raise_for_error
    raise CellExecutionError.from_cell_and_msg(cell, exec_reply_content)
nbclient.exceptions.CellExecutionError: An error occurred while executing the following cell:
------------------
import numpy as np
import neuroboros as nb
import hyperalignment as ha
import matplotlib.pyplot as plt
from scipy.stats import zscore
------------------

[0;31m---------------------------------------------------------------------------[0m
[0;31mImportError[0m                               Traceback (most recent call last)
[0;32m<ipython-input-1-6693c57c0e2c>[0m in [0;36m<module>[0;34m[0m
[1;32m      1[0m [0;32mimport[0m [0mnumpy[0m [0;32mas[0m [0mnp[0m[0;34m[0m[0;34m[0m[0m
[0;32m----> 2[0;31m [0;32mimport[0m [0mneuroboros[0m [0;32mas[0m [0mnb[0m[0;34m[0m[0;34m[0m[0m
[0m[1;32m      3[0m [0;32mimport[0m [0mhyperalignment[0m [0;32mas[0m [0mha[0m[0;34m[0m[0;34m[0m[0m
[1;32m      4[0m [0;32mimport[0m [0mmatplotlib[0m[0;34m.[0m[0mpyplot[0m [0;32mas[0m [0mplt[0m[0;34m[0m[0;34m[0m[0m
[1;32m      5[0m [0;32mfrom[0m [0mscipy[0m[0;34m.[0m[0mstats[0m [0;32mimport[0m [0mzscore[0m[0;34m[0m[0;34m[0m[0m

[0;32m~/github/neuroboros/src/neuroboros/__init__.py[0m in [0;36m<module>[0;34m[0m
[1;32m     18[0m [0;32mfrom[0m [0;34m.[0m[0mutils[0m [0;32mimport[0m [0msave_results[0m [0;32mas[0m [0mrecord[0m[0;34m[0m[0;34m[0m[0m
[1;32m     19[0m [0;31m# from . import idm as idm[0m[0;34m[0m[0;34m[0m[0;34m[0m[0m
[0;32m---> 20[0;31m [0;32mfrom[0m [0;34m.[0m[0mplot2d[0m [0;32mimport[0m [0mbrain_plot[0m [0;32mas[0m [0mplot[0m[0;34m[0m[0;34m[0m[0m
[0m[1;32m     21[0m [0;31m# from . import stats as stats[0m[0;34m[0m[0;34m[0m[0;34m[0m[0m
[1;32m     22[0m [0;32mfrom[0m [0;34m.[0m [0;32mimport[0m [0mlinalg[0m [0;32mas[0m [0mlinalg[0m[0;34m[0m[0;34m[0m[0m

[0;32m~/github/neuroboros/src/neuroboros/plot2d.py[0m in [0;36m<module>[0;34m[0m
[1;32m     20[0m     [0mipython_ok[0m [0;34m=[0m [0;32mFalse[0m[0;34m[0m[0;34m[0m[0m
[1;32m     21[0m [0;34m[0m[0m
[0;32m---> 22[0;31m [0;32mfrom[0m [0;34m.[0m[0mio[0m [0;32mimport[0m [0mload_file[0m[0;34m[0m[0;34m[0m[0m
[0m[1;32m     23[0m [0;32mfrom[0m [0;34m.[0m[0mspaces[0m [0;32mimport[0m [0mget_mapping[0m[0;34m,[0m [0mget_mask[0m[0;34m[0m[0;34m[0m[0m
[1;32m     24[0m [0;32mfrom[0m [0;34m.[0m[0mutils[0m [0;32mimport[0m [0msave[0m[0;34m[0m[0;34m[0m[0m

[0;31mImportError[0m: cannot import name 'load_file' from 'neuroboros.io' (/Users/feilong/github/neuroboros/src/neuroboros/io.py)
ImportError: cannot import name 'load_file' from 'neuroboros.io' (/Users/feilong/github/neuroboros/src/neuroboros/io.py)

